Workbook

Sheet Items
A1: ItemID | B1: LastName | C1: FirstName | D1: FullName | E1: Title | F1: College | G1: Department | H1: Email | I1: ItemType | J1: ItemTitle | K1: Year | L1: Venue / Funder | M1: Authors / Investigators | N1: Role | O1: Amount (USD) | P1: AwardID / PatentNo | Q1: DOI | R1: URL | S1: Sources | T1: SourceCount | U1: Confidence | V1: ScholarCitations | W1: CitationAsListed | X1: Abstract | Y1: AbstractSource | Z1: FullTextURL | AA1: FullTextType | AB1: OpenAccessStatus | AC1: School | AD1: Citations (OpenAlex) | AE1: AI-related | AF1: AI evidence | AG1: Check | AH1: Correction notes | AI1: Reviewed by
A2: AAS-0001 | B2: Botchway | C2: Karl | D2: Karl Botchway | E2: Associate Professor | F2: NYC College of Technology | G2: African American Studies | H2: karl.botchway07@citytech.cuny.edu | I2: Paper (venue type unclear) | J2: Botchway is a member of the African Studies Association, American Political Science Association, and The Academy of Political Science | S2: Dept bio | T2: 1 | U2: Medium (self-reported in faculty bio) | W2: Dr. Botchway is a member of the African Studies Association, American Political Science Association, and The Academy of Political Science. | AC2: School of Arts & Sciences | AE2: No
A3: AAS-0002 | B3: Botchway | C3: Karl | D3: Karl Botchway | E3: Associate Professor | F3: NYC College of Technology | G3: African American Studies | H3: karl.botchway07@citytech.cuny.edu | I3: Journal article | J3: Are Development Planners Afraid of History and Contextualization? Notes on Reading a Development Report on Northern Ghana | K3: 2001 | L3: Canadian Journal of African Studies / Revue canadienne des études africaines | M3: Karl Botchway | Q3: 10.1080/00083968.2001.10751216 | R3: https://doi.org/10.1080/00083968.2001.10751216 | S3: OpenAlex; Dept bio | T3: 2 | U3: High (City Tech affiliation on paper); 2 sources | W3: Are Development Planners Afraid of History and Contextualization? Notes on Reading a Development Report on Northern Ghana, Canadian Journal of African Studies, Volume 35, #1, 2001 | X3: Lorsqu’elles présentent leurs arguments en faveur du développement, estce que les agences de développement internationales analysent les sociétés qu’elles s’efforcent de développer comme des organismes engagées dans un processus historique plus large ou les voient-elles comme des sociétés isolées avec seulement quelques contacts sporadiques avec le monde extérieur? Cet article, analysant le cas d’un projet de développement rural dans la région nord du Ghana, conjointement financé par le Ghana et le Canada, affirme que les questions concernant le développement de cette région avaient été présentées comme si la pauvreté de la région était uniquement la conséquence des caractéristiques bio-physiques de la région et d’une piètre application des principes économiques. Cet article remet en question une telle emphase et déclare que le cas du projet de développement dans le Ghana du nord n’a pas été replacé dans son contexte et n’a pas suffisamment tenu compte de son histoire pour explorer les causes politiques, économiques et structurelles à long terme de la pauvreté dans cette région. Ce faisant, les questions contestées sur les causes socio-politiques et structurelles de la pauvreté deviennent dépolitisées. | Y3: OpenAlex | Z3: https://doi.org/10.2307/486346 | AA3: Not found | AB3: closed | AC3: School of Arts & Sciences | AD3: 4 | AE3: No
A4: AAS-0003 | B4: Botchway | C4: Karl | D4: Karl Botchway | E4: Associate Professor | F4: NYC College of Technology | G4: African American Studies | H4: karl.botchway07@citytech.cuny.edu | I4: Journal article | J4: Paradox of Empowerment: Reflections on a Case Study from Northern Ghana | K4: 2001 | L4: World Development | M4: Karl Botchway | Q4: 10.1016/s0305-750x(00)00084-x | R4: https://doi.org/10.1016/s0305-750x(00)00084-x | S4: OpenAlex; Dept bio | T4: 2 | U4: High (City Tech affiliation on paper); 2 sources | W4: Paradox of Empowerment: Reflections on a Case Study from Northern Ghana, World Development Vol. 29, #1, 2001 | AA4: Not found | AB4: closed | AC4: School of Arts & Sciences | AD4: 155 | AE4: No
A5: AAS-0004 | B5: Botchway | C5: Karl | D5: Karl Botchway | E5: Associate Professor | F5: NYC College of Technology | G5: African American Studies | H5: karl.botchway07@citytech.cuny.edu | I5: Paper (venue type unclear) | J5: Understanding "Development" Interventions in Northern Ghana, Edwin Mellen Press, Lewiston, NY, 2004 | K5: 2004 | S5: Dept bio | T5: 1 | U5: Medium (self-reported in faculty bio) | W5: Understanding "Development" Interventions in Northern Ghana, Edwin Mellen Press, Lewiston, NY, 2004 | AC5: School of Arts & Sciences | AE5: No
A6: AAS-0005 | B6: Biswas | C6: Debarati | D6: Debarati Biswas | E6: Assistant Professor | F6: NYC College of Technology | G6: African American Studies | H6: debarati.biswas57@citytech.cuny.edu | I6: Journal article | J6: Beyond the Parasitical Logic in Octavia Butler's Fledgling (2005) | K6: 2005 | M6: Chapter in Edited Book: “Beyond the Parasitical Logic in Octavia Butler's Fledgling | S6: Dept bio | T6: 1 | U6: Medium (self-reported in faculty bio) | W6: Chapter in Edited Book: “Beyond the Parasitical Logic in Octavia Butler's Fledgling (2005).” Parasitical Logic in Culture and Society. Ed. By Peter Hitchcock. Bloomsbury Publishing, 2026. Journals: Articles in Refereed Journals: Unbearable Being(s). Special Issue, WSQ: Women’s Studies Quarterly, vol. 52, numbers 3&4. Fall/Winter, 2024. Co-guest editor with Laura Westengard. “Rehearsals for Living Within the Unbearable: Tracking Possibilities of Love and Solidarity in Black Art and Literature.” Special Issue, WSQ: Women's Studies Quarterly 52, no. 3 (2024): 283-296. “Rituals of Survival in Single Room Occupancy Hotels,” Social Text, 158, vol. 42. issue 1, March 2024. Co-authored with Kirin Wachter Grene. Other Publications: “New College of Florida: The Conservative Christian Takeover by Ron DeSantis, Chris Rufo.” Teen Vogue: Politics, March 2023. Co-authored with Erik Wallenberg. “How to Subvert the Capitalist White-Supremacist University.” Public Books, May 2020. | AC6: School of Arts & Sciences | AE6: No
A7: AAS-0006 | B7: Botchway | C7: Karl | D7: Karl Botchway | E7: Associate Professor | F7: NYC College of Technology | G7: African American Studies | H7: karl.botchway07@citytech.cuny.edu | I7: Paper (venue type unclear) | J7: The Politics and Apolitics of Development: The Case of Development Project in Northern Ghana, in Kwadwo Konadu-Agyemang and Kwamina Panford (eds.) Africa's Development in the Twenty-first Century, Ashgate Publishing Company, Burlington, VT, 2006 | K7: 2006 | S7: Dept bio | T7: 1 | U7: Medium (self-reported in faculty bio) | W7: The Politics and Apolitics of Development: The Case of Development Project in Northern Ghana, in Kwadwo Konadu-Agyemang and Kwamina Panford (eds.) Africa's Development in the Twenty-first Century, Ashgate Publishing Company, Burlington, VT, 2006 | AC7: School of Arts & Sciences | AE7: No
A8: AAS-0007 | B8: Botchway | C8: Karl | D8: Karl Botchway | E8: Associate Professor | F8: NYC College of Technology | G8: African American Studies | H8: karl.botchway07@citytech.cuny.edu | I8: Journal article | J8: Challenging the Orthodoxy: African Development in the Age of Openness | K8: 2007 | L8: African and Asian Studies | M8: Jamee K. Moudud; Karl Botchway | Q8: 10.1163/156921007x236981 | R8: https://doi.org/10.1163/156921007x236981 | S8: OpenAlex; Dept bio | T8: 2 | U8: High (City Tech affiliation on paper); 2 sources | W8: Challenging the Orthodoxy: African Development in the Age of Openness, African and Asian Studies, Volume 6, #4, 2007. (With Jamee Moudud) | X8: Abstract Does trade openness necessarily lead to income convergence between countries in the North and South and hence facilitates social development? This paper challenges this claim with regards to African development in the age of neo-liberalism. The paper argues that a one-sided reading of the history of an early phase of globalization by advocates of neo-liberalism seems to have turned trade openness into a mantra for African development. Furthermore the paper challenges the rhetoric of competitiveness that underpins the rationale for neo-liberalism by critiquing the neoclassical model of competition. The neo-liberal policy position, as the paper suggests is problematic at an empirical level also. In a test for convergence for eleven sub-Saharan African countries described as good adjusters by advocates of trade openness, the paper shows that a straightforward openness per se guarantees nothing as far their growth rates are concerned. Rather this paper suggests that the role of the “developmental state” needs to be brought back in order to facilitate the international competitiveness of African countries. It will be argued that such a role for the developmental state rests on a very different conceptualization of the nature of capitalist competition and growth. In the final instance, then, we suggest the need for building a theory of the developmental state that rests on non-neoclassical macro- and micro-foundations. | Y8: OpenAlex | AA8: Not found | AB8: closed | AC8: School of Arts & Sciences | AD8: 4 | AE8: No
A9: AAS-0010 | B9: Botchway | C9: Karl | D9: Karl Botchway | E9: Associate Professor | F9: NYC College of Technology | G9: African American Studies | H9: karl.botchway07@citytech.cuny.edu | I9: Journal article | J9: The Search for a New Developmental State | K9: 2008 | L9: International Journal of Political Economy | M9: Jamee K. Moudud; Karl Botchway | Q9: 10.2753/ijp0891-1916370301 | R9: https://doi.org/10.2753/ijp0891-1916370301 | S9: OpenAlex; Dept bio | T9: 2 | U9: High (City Tech affiliation on paper); 2 sources | W9: The Search for a New Developmental State, International Journal of Political Economy, vol. 37, no. 3, Fall 2008. (With Jamee Moudud) | X9: (2008). The Search for a New Developmental State. International Journal of Political Economy: Vol. 37, No. 3, pp. 5-26. | Y9: OpenAlex | AA9: Not found | AB9: closed | AC9: School of Arts & Sciences | AD9: 6 | AE9: No
A10: AAS-0013 | B10: Botchway | C10: Karl | D10: Karl Botchway | E10: Associate Professor | F10: NYC College of Technology | G10: African American Studies | H10: karl.botchway07@citytech.cuny.edu | I10: Paper (venue type unclear) | J10: Neo-Liberalism and the Developmental State: Considerations for the New Partnership For Africa’s Development, in Benjamin F. Bobo and Hermann Sintim-Aboagye, Neo-Liberalism, Interventionism and the Developmental State, Africa World Press, Trenton, NJ, 2012 | K10: 2012 | S10: Dept bio | T10: 1 | U10: Medium (self-reported in faculty bio) | W10: Neo-Liberalism and the Developmental State: Considerations for the New Partnership For Africa’s Development, in Benjamin F. Bobo and Hermann Sintim-Aboagye, Neo-Liberalism, Interventionism and the Developmental State, Africa World Press, Trenton, NJ, 2012. (With Jamee Moudud) | AC10: School of Arts & Sciences | AE10: No
A11: AAS-0023 | B11: Ferdinand | C11: Renata | D11: Renata Ferdinand | E11: Chair | F11: NYC College of Technology | G11: African American Studies | H11: Renata.Ferdinand92@citytech.cuny.edu | I11: Journal article | J11: Writing Home | K11: 2014 | L11: Space and Culture | M11: Renata Harden Ferdinand | Q11: 10.1177/1206331213510445 | R11: https://doi.org/10.1177/1206331213510445 | S11: OpenAlex | T11: 1 | U11: High (City Tech affiliation on paper) | X11: Africa as an ancestral home is a prominent theme among African Americans. Many have sojourned to Africa in the hopes of establishing a cultural or spiritual connection with the continent. This essay investigates the ways in which African Americans encounter African culture and space. Specifically, this is an auto-ethnographic essay that details the author’s diasporic identity transformation as a result of visiting the West African nation of Burkina Faso. Enabled by educational courses and through a living arrangement with a host family, the author establishes how Burkina Faso became a surrogate home. | Y11: OpenAlex | AA11: Not found | AB11: closed | AC11: School of Arts & Sciences | AD11: 7 | AE11: No
A12: AAS-0026 | B12: Ferdinand | C12: Renata | D12: Renata Ferdinand | E12: Chair | F12: NYC College of Technology | G12: African American Studies | H12: Renata.Ferdinand92@citytech.cuny.edu | I12: Journal article | J12: It’s like a black woman’s Charlie Brown moment: An autoethnography of being diagnosed with lupus | K12: 2016 | L12: Journal of Health Psychology | M12: Renata Harden Ferdinand | Q12: 10.1177/1359105316664128 | R12: https://doi.org/10.1177/1359105316664128 | S12: OpenAlex | T12: 1 | U12: High (City Tech affiliation on paper) | X12: This essay uses autoethnography to relate the experience of being diagnosed with lupus. By using my personal experiences and a discussion of illness and Black women's health, I critically examine larger critical race issues of race, gender, and the social barriers to health care. Specifically, the essay focuses on the ways in which race impacts my experiences with the healthcare system, from my own insecurities of being stereotyped to the ways that doctors interact with me. The essay is framed by popular quotes from Charlie Brown because they help mediate the very personal experiences I am recounting. | Y12: OpenAlex | AA12: Not found | AB12: closed | AC12: School of Arts & Sciences | AD12: 5 | AE12: No
A13: AAS-0028 | B13: Ferdinand | C13: Renata | D13: Renata Ferdinand | E13: Chair | F13: NYC College of Technology | G13: African American Studies | H13: Renata.Ferdinand92@citytech.cuny.edu | I13: Journal article | J13: Remember, Me: An Interlocking Narrative of Black Women’s Past and Present | K13: 2017 | L13: Culture Studies &#x2194 Critical Methodologies | M13: Renata Harden Ferdinand | Q13: 10.1177/1532708617744575 | R13: https://doi.org/10.1177/1532708617744575 | S13: OpenAlex | T13: 1 | U13: High (City Tech affiliation on paper) | X13: This is a postcolonial autoethnography that explores the historical and contemporary plight of African American women. Specifically, it uses narrative and performative writing to demonstrate how both groups operate within similar systems of domination, leading to their existence as a disenfranchised, liminal group. By bridging the past with the present, the author draws a parallel between the lives of contemporary Black women and their historical predecessors, thereby showing the connection between seemingly disparate historical events. Furthermore, this essay examines the author’s particular location as a diasporic subject, exploring how she exists in an illusion of freedom, and with a disjointed subjectivity. Summarily, this essay examines larger issues of race, gender, and the identity politics of the diasporic subject, all in an effort to show how the past is recapitulated into the present. It offers a more nuanced way of thinking about the past, present, and the future. | Y13: OpenAlex | AA13: Not found | AB13: closed | AC13: School of Arts & Sciences | AD13: 7 | AE13: No
A14: AAS-0032 | B14: Evangelista | C14: Javiela | D14: Javiela Evangelista | E14: Associate Professor | F14: NYC College of Technology | G14: African American Studies | H14: javiela.evangelista75@citytech.cuny.edu | I14: Open educational resource | J14: The Heritage of Imperialism, AFR 2402 ID, Course Outline | K14: 2018 | L14: Open Educational Resources | M14: Evangelista, Javiela | R14: https://academicworks.cuny.edu/ny_oers/64 | S14: CUNY Academic Works | T14: 1 | U14: High (in CUNY Academic Works) | X14: This course offers an examination of the thought, structure, operation and results of imperialism in human history generally, and in the 19th/21st centuries in particular. We will use readings and films to examine European/American imperialism in the non-white areas of the world: the role of the Industrial Revolution; the imposition of Western European institutions on indigenous peoples of Africa, Asia, North/South America; colonialism; attempts by these people to reestablish autonomous sociological and cultural systems. | Y14: CUNY Academic Works | Z14: https://academicworks.cuny.edu/context/ny_oers/article/1073/viewcontent/auto_convert.pdf | AA14: PDF in CUNY Academic Works | AC14: School of Arts & Sciences | AE14: No
A15: AAS-0033 | B15: Effinger-Crichlow | C15: Marta | D15: Marta Effinger-Crichlow | E15: Professor | F15: NYC College of Technology | G15: African American Studies | H15: marta.effinger-crichlow45@citytech.cuny.edu | I15: Book chapter | J15: A Pedagogical Search for Home and Care | K15: 2019 | L15: University of Minnesota Press eBooks | M15: Marta Effinger-Crichlow | Q15: 10.5749/j.ctvg251hk.43 | R15: https://doi.org/10.5749/j.ctvg251hk.43 | S15: OpenAlex; CUNY Academic Works | T15: 2 | U15: High (City Tech affiliation on paper); 2 sources | Z15: https://academicworks.cuny.edu/context/ny_pubs/article/1485/viewcontent/effinger.pdf | AA15: Not found | AB15: closed | AC15: School of Arts & Sciences | AD15: 0 | AE15: No
A16: AAS-0036 | B16: Evangelista | C16: Javiela | D16: Javiela Evangelista | E16: Associate Professor | F16: NYC College of Technology | G16: African American Studies | H16: javiela.evangelista75@citytech.cuny.edu | I16: Book chapter | J16: Deconstructing the Heritage of Imperialism Toward Life-Long Learning: High-Impact Practices that Further Student Self-Actualization and Social Justice Analyses | K16: 2020 | L16: Springer eBooks | M16: Javiela Evangelista | Q16: 10.1007/978-3-030-56302-8_6 | R16: https://doi.org/10.1007/978-3-030-56302-8_6 | S16: OpenAlex | T16: 1 | U16: High (City Tech affiliation on paper) | AA16: Not found | AB16: closed | AC16: School of Arts & Sciences | AD16: 1 | AE16: No
A17: AAS-0047 | B17: Ferdinand | C17: Renata | D17: Renata Ferdinand | E17: Chair | F17: NYC College of Technology | G17: African American Studies | H17: Renata.Ferdinand92@citytech.cuny.edu | I17: Journal article | J17: Black Women, Black Girls, and the Covid-19 Pandemic: An Autoethnography of a Health Disparity | K17: 2022 | L17: Culture Studies &#x2194 Critical Methodologies | M17: Renata Harden Ferdinand; Rajah Emahn Ferdinand | Q17: 10.1177/15327086221087666 | R17: https://doi.org/10.1177/15327086221087666 | S17: OpenAlex | T17: 1 | U17: High (City Tech affiliation on paper) | X17: This is an autoethnographic essay that explores how the Covid-19 pandemic affect(ed) Black women and girls. Through storytelling and narrative and performative writing, it paints a clearer picture of the lives lost due to the coronavirus by highlighting specific tragedies that occurred, and by examining the larger societal context that allowed such tragedies to unfold. In addition, it offers an intimate look at the emotional processes that occur when one is diagnosed with the virus. | Y17: OpenAlex | AA17: Not found | AB17: closed | AC17: School of Arts & Sciences | AD17: 1 | AE17: No
A18: AAS-0048 | B18: Ferdinand | C18: Renata | D18: Renata Ferdinand | E18: Chair | F18: NYC College of Technology | G18: African American Studies | H18: Renata.Ferdinand92@citytech.cuny.edu | I18: Journal article | J18: Teaching Black Girlhood Studies with Black Motherhood Studies | K18: 2022 | L18: Girlhood Studies | M18: Renata Harden Ferdinand | Q18: 10.3167/ghs.2022.150306 | R18: https://doi.org/10.3167/ghs.2022.150306 | S18: OpenAlex | T18: 1 | U18: High (City Tech affiliation on paper) | X18: What is the relationship between Black Girlhood Studies and Black Motherhood Studies? In this article I answer this question by considering the ways in which these subjects can be explored together or in relation to each other. Using autoethnography, I describe the process of teaching Black Girlhood Studies with Black Motherhood Studies. Specifically, through narrative and performative writing, I draw upon my own personal experience of using research and scholarship associated with Black Girlhood Studies to inform and provide a foundation for the exploration of Black Motherhood Studies in an effort to promote a fuller, more complete and nuanced understanding of both social positions. | Y18: OpenAlex | AA18: Not found | AB18: closed | AC18: School of Arts & Sciences | AD18: 2 | AE18: No
A19: AAS-0050 | B19: Evangelista | C19: Javiela | D19: Javiela Evangelista | E19: Associate Professor | F19: NYC College of Technology | G19: African American Studies | H19: javiela.evangelista75@citytech.cuny.edu | I19: Conference presentation | J19: Implicit Bias Among Health Professionals | K19: 2023 | L19: Publications and Research | M19: Toussaint, Kimora H.; Evangelista, Javiela | R19: https://academicworks.cuny.edu/ny_pubs/1141 | S19: CUNY Academic Works | T19: 1 | U19: High (in CUNY Academic Works) | X19: Racism and implicit bias are prevalent in healthcare, which may affect patient well-being. One way implicit bias is most evident is in language. Negative descriptors, such as âsicklerââa term used for those diagnosed with Sickle Cell Disease (SCD), influence how health providers view their patients and determine pain medication prescriptions (Goddu et al.). Patient experience, such as prior use of opioids or using words that imply substance abuse, may block patients from accessing prescriptions and proper care. Black, Indigenous, and People of Color (BIPOC) are disproportionately affected by such negative descriptors (Sun et al., 2022). Among other adverse impacts, treating patient pain accounts for mental health or sleep issues and increases the number of unnecessary visits to the hospital (Keister et al., 2016). How patients are described in their Electronic Medical Records (EMRs) reveals prejudice in health practices, which may prevent adequate care and impact interactions with future health providers. Prejudices and biases are also presented in non-verbal communication, such as glances or facial expressions. This poster will include an analysis of peer-reviewed articles on data collection experiments and language use in Electronic Medical Records. In the end, methods for health professionals to acknowledge and address their unconscious biases, including health equity education, will be presented (Cooper et al., Healy et al.). | Y19: CUNY Academic Works | Z19: https://academicworks.cuny.edu/context/ny_pubs/article/2170/viewcontent/Implicit_Bias_Among_Health_Professionals.pdf | AA19: PDF in CUNY Academic Works | AC19: School of Arts & Sciences | AE19: No
A20: ARCH-0003 | B20: Anzalone | C20: Phillip | D20: Phillip Anzalone | E20: Associate Professor | F20: NYC College of Technology | G20: Architectural Technology | H20: PAnzalone@citytech.cuny.edu | I20: Journal article | J20: Trusset: Parallel Development of Software and Construction Systems for Space-Truss Structures | K20: 2004 | L20: International Journal of Architectural Computing | M20: Cory Clarke; Phillip Anzalone | Q20: 10.1260/1478077041518700 | R20: https://doi.org/10.1260/1478077041518700 | S20: OpenAlex; CUNY Academic Works | T20: 2 | U20: High (City Tech affiliation on paper); 2 sources | X20: This paper documents our current progress on the parallel development of a building system and corresponding agent-based software design tools; together the two produce a seamless pipeline from design to fabrication and assembly. The building system is a clad differential space-truss designed for fabrication entirely with computer numerically controlled (CNC) linear cutting devices such as CNC laser cutters or two-axis mills. The software component is a set of agent-based design tools for developing surfaces and envelopes formally suitable to be built using our space-truss system. | Y20: OpenAlex | Z20: https://academicworks.cuny.edu/context/ny_pubs/article/1192/viewcontent/ijac20032206.content.pdf | AA20: Not found | AB20: closed | AC20: School of Technology & Design | AD20: 2 | AE20: No
A21: ARCH-0010 | B21: Anzalone | C21: Phillip | D21: Phillip Anzalone | E21: Associate Professor | F21: NYC College of Technology | G21: Architectural Technology | H21: PAnzalone@citytech.cuny.edu | I21: Conference paper | J21: Non-Uniform Assemblage: Mass Customization in Digital Fabrication | K21: 2008 | L21: ScholarWorks@UMassAmherst (University of Massachusetts Amherst) | M21: Phillip Anzalone; Joseph Vidich; Joshua Draper | R21: https://openalex.org/W1558420933 | S21: OpenAlex; CUNY Academic Works | T21: 2 | U21: High (City Tech affiliation on paper); 2 sources | X21: This paper focuses on the development of parametric detailing, mass customization in CNC fabrication and its computational and handcrafted realizations in actualized built work.The projects studied are examples of student and faculty applied research work at Columbia University's Graduate School of Architecture that engage parametric design strategies to integrate digital fabrication processes with manual assembly procedures, including prefabricated components and assemblies.The presented case studies include the design, fabrication and assembly of two full-scale pavilion projects. | Y21: OpenAlex | Z21: https://scholarworks.umass.edu/wood/2008/sept27/8 | AA21: Open-access PDF (via OpenAlex) | AB21: green | AC21: School of Technology & Design | AD21: 3 | AE21: No
A22: ARCH-0016 | B22: Anzalone | C22: Phillip | D22: Phillip Anzalone | E22: Associate Professor | F22: NYC College of Technology | G22: Architectural Technology | H22: PAnzalone@citytech.cuny.edu | I22: Journal article | J22: Framing Space | K22: 2010 | L22: Publications and Research | M22: Anzalone, Phillip; Bayard, Stephanie | R22: https://academicworks.cuny.edu/ny_pubs/976 | S22: CUNY Academic Works | T22: 1 | U22: High (in CUNY Academic Works) | Z22: https://academicworks.cuny.edu/context/ny_pubs/article/2004/viewcontent/ACSA.AM.98.54.pdf | AA22: PDF in CUNY Academic Works | AC22: School of Technology & Design | AE22: No
A23: ARCH-0019 | B23: Vaidya | C23: Sanjive | D23: Sanjive Vaidya | E23: Associate Professor | F23: NYC College of Technology | G23: Architectural Technology | H23: SVaidya@citytech.cuny.edu | I23: Grant | J23: 2011-2015 CO-PI for NSF‐ ATE Grant: FuseLab: Director of Sustainability and Building Performance | K23: 2011 | N23: Co-PI | S23: Dept bio | T23: 1 | U23: Medium (self-reported in faculty bio) | W23: 2011-2015 CO-PI for NSF‐ ATE Grant: FuseLab: Director of Sustainability and Building Performance | AC23: School of Technology & Design | AE23: No
A24: ARCH-0020 | B24: Vaidya | C24: Sanjive | D24: Sanjive Vaidya | E24: Associate Professor | F24: NYC College of Technology | G24: Architectural Technology | H24: SVaidya@citytech.cuny.edu | I24: Grant | J24: 2011-2015 Design_Serv : Mentoring Program Director | K24: 2011 | S24: Dept bio | T24: 1 | U24: Medium (self-reported in faculty bio) | W24: 2011-2015 Design_Serv : Mentoring Program Director | AC24: School of Technology & Design | AE24: No
A25: ARCH-0021 | B25: Smith | C25: Shelley | D25: Shelley Smith | E25: Professor | F25: NYC College of Technology | G25: Architectural Technology | H25: SSmith@citytech.cuny.edu | I25: Grant | J25: Fuse Lab: Collaborative Education for Tomorrow's Technology in Architecture, Engineering, and Construction | K25: 2011 | L25: NSF: Advanced Tech Education Prog | M25: Shelley Smith; Huseyin Yuce; Gerarda M Shields; Anne Leonhardt; Marie Segares | N25: PI | O25: 877322 | P25: 1104254 | R25: https://www.nsf.gov/awardsearch/showAward?AWD_ID=1104254 | S25: NSF | T25: 1 | U25: High (NSF award to City Tech) | X25: New York City College of Technology (City Tech) in collaboration with Polytechnic High School of Engineering, Architecture and Technology (City Poly) and industry partners are implementing an initiative titled Fuse Lab in an effort to transform the AEC (architecture, engineering and construction) curriculum and develop faculty expertise. This initiative provides a model for other undergraduate AEC programs around the country. In order to produce students who can take advantage of and continuously adapt to the fields' rapidly evolving computational, construction and sustainable technologies, Fuse lab is 1) developing and implementing an articulated career pathway (3+2+2) that serves a diverse population of students and leads to the associate and baccalaureate degree while offering students multiple exit points that were integrated with industry certification; 2) creating curriculum units and faculty development opportunities that reflect the technology integration and interdisciplinary team work that have transformed industry practice; and 3) situating these activities in a larger advanced technology loop by creating sustainable mechanisms for industry participation across the career pathway and by joining existing feedback loops with ATE centers and related projects. The broader impact of the project includes addressing future needs of AEC technicians, increasing participation of underrepresented populations and producing a new AEC curriculum that can serve as a national model. | Y25: NSF | AC25: School of Technology & Design | AE25: No
A26: ARCH-0022 | B26: Leonhardt | C26: Anne | D26: Anne Leonhardt | E26: Associate Professor | F26: NYC College of Technology | G26: Architectural Technology | H26: ALeonhardt@citytech.cuny.edu | I26: Grant | J26: Fuse Lab: Collaborative Education for Tomorrow's Technology in Architecture, Engineering, and Construction | K26: 2011 | L26: NSF: Advanced Tech Education Prog | M26: Shelley Smith; Huseyin Yuce; Gerarda M Shields; Anne Leonhardt; Marie Segares | N26: Co-PI | O26: 877322 | P26: 1104254 | R26: https://www.nsf.gov/awardsearch/showAward?AWD_ID=1104254 | S26: NSF | T26: 1 | U26: High (NSF award to City Tech) | X26: New York City College of Technology (City Tech) in collaboration with Polytechnic High School of Engineering, Architecture and Technology (City Poly) and industry partners are implementing an initiative titled Fuse Lab in an effort to transform the AEC (architecture, engineering and construction) curriculum and develop faculty expertise. This initiative provides a model for other undergraduate AEC programs around the country. In order to produce students who can take advantage of and continuously adapt to the fields' rapidly evolving computational, construction and sustainable technologies, Fuse lab is 1) developing and implementing an articulated career pathway (3+2+2) that serves a diverse population of students and leads to the associate and baccalaureate degree while offering students multiple exit points that were integrated with industry certification; 2) creating curriculum units and faculty development opportunities that reflect the technology integration and interdisciplinary team work that have transformed industry practice; and 3) situating these activities in a larger advanced technology loop by creating sustainable mechanisms for industry participation across the career pathway and by joining existing feedback loops with ATE centers and related projects. The broader impact of the project includes addressing future needs of AEC technicians, increasing participation of underrepresented populations and producing a new AEC curriculum that can serve as a national model. | Y26: NSF | AC26: School of Technology & Design | AE26: No
A27: ARCH-0023 | B27: King | C27: Paul | D27: Paul King | E27: Professor | F27: NYC College of Technology | G27: Architectural Technology | H27: PKing@citytech.cuny.edu | I27: Journal article | J27: Technology and Teaching Philosophy | K27: 2011 | L27: Journal of Educational Technology Systems | M27: Paul C. King | Q27: 10.2190/et.40.2.f | R27: https://doi.org/10.2190/et.40.2.f | S27: OpenAlex | T27: 1 | U27: High (City Tech affiliation on paper) | X27: This article discusses the challenges faced when integrating new technologies into the classroom. Viewing the experiences of teaching a first year learning community through the lens of the principles of the Reflective Teaching Portfolio, the author looks to answer the question: How should Technology relate to our Teaching Philosophy? While a proponent of testing and integrating new technologies into the classroom, the author also recognizes that we learn more from our mistakes than from our successes and that if a tool does not fit with our Teaching Philosophy, then we should not use it. This article provides an honest assessment of recent experiences integrating online learning technologies into the classroom and makes suggestions on how to develop a successful approach. | Y27: OpenAlex | AA27: Not found | AB27: closed | AC27: School of Technology & Design | AD27: 5 | AE27: No
A28: ARCH-0024 | B28: Leonhardt | C28: Anne | D28: Anne Leonhardt | E28: Associate Professor | F28: NYC College of Technology | G28: Architectural Technology | H28: ALeonhardt@citytech.cuny.edu | I28: Grant | J28: Center for Performative Design and Engineering Technology: Pioneering Performative Processes in Design and Engineering Technology Education | K28: 2012 | L28: NSF: S-STEM-Schlr Sci Tech Eng&Math, TUES-Type 1 Project | M28: Anne Leonhardt; John McCullough; Adam Wilson; Iem Heng (Former); Anne Leonhardt (Former) | N28: PI | O28: 199820 | P28: 1141234 | R28: https://www.nsf.gov/awardsearch/showAward?AWD_ID=1141234 | S28: NSF | T28: 1 | U28: High (NSF award to City Tech) | X28: The School of Technology and Design at New York City College of Technology proposes to create a new Center for Performative Design and Engineering Technology that will pioneer performative design education. The project takes as its inspiration the broad focus on laboratory-based learning that brings technological education to a higher level of integration and broader faculty engagement across an entire division. The Center will become the focus of interdisciplinary project-based learning for faculty and students from its nine constituent departments where they will conduct research projects using state-of-the-art technologies in cross-cutting applications that mirror industry practice. The project will produce a laboratory design to support interdisciplinary research by configuring equipment and instrumentation for optimal collaborative use. A faculty team will create a web-based tutorial system for asynchronous learning to accompany interdisciplinary applications of cutting-edge technology. They will also design a new interdisciplinary capstone course and four cross-disciplinary projects for baccalaureate-level students. This project will provide a model for other institutions with similar programs to emulate. By bringing project-based interdisciplinary team collaborations to the fore, the project will contribute to an on-going paradigm shift in the way engineering design is taught. The project will also broaden participation since New York City College of Technology serves a high percentage of underrepresented minority students and is one of the nation's top producers of underrepresented minority associate degree graduates in STEM fields. | Y28: NSF | AC28: School of Technology & Design | AE28: No
A29: ARCH-0027 | B29: Smith | C29: Shelley | D29: Shelley Smith | E29: Professor | F29: NYC College of Technology | G29: Architectural Technology | H29: SSmith@citytech.cuny.edu | I29: Preprint | J29: Bounding the distinguishing number of infinite graphs | K29: 2013 | L29: arXiv (Cornell University) | M29: Simon M. Smith; Mark E. Watkins | Q29: 10.48550/arxiv.1302.4409 | R29: https://doi.org/10.48550/arxiv.1302.4409 | S29: OpenAlex | T29: 1 | U29: High (City Tech affiliation on paper) | X29: A group of permutations G of a set V is k-distinguishable if there exists a partition of V into k parts such that only the identity permutation in G fixes setwise all of the cells of the partition. The least cardinal number k such that (G,V) is k-distinguishable is its distinguishing number. In particular, a graph X is k-distinguishable if its automorphism group Aut(X) has distinguishing number at most k in its action on the vertices of X. Various results in the literature demonstrate that when an infinite graph fails to have some property, then often some finite subgraph is similarly deficient. In this paper we show that whenever an infinite connected graph X is not k-distinguishable (for a given cardinal k), then it contains a ball B of finite radius whose distinguishing number is at least k. Moreover, this lower bound cannot be sharpened, since for any integer k greater than 3 there exists an infinite, locally finite, connected graph X that is not k-distinguishable but in which every ball of finite radius is k-distinguishable. In the second half of this paper we show that a large distinguishing number for an imprimitive graph X is traceable to a high distinguishing number either of a block of imprimitivity or of the induced action of Aut(X) on the corresponding system of imprimitivity. The distinguishing numbers of infinite primitive graphs have been examined in detail in a previous paper by the authors together with Tom W. Tucker. | Y29: OpenAlex | Z29: https://arxiv.org/pdf/1302.4409 | AA29: Open-access PDF (via OpenAlex) | AB29: green | AC29: School of Technology & Design | AD29: 1 | AE29: No
A30: ARCH-0029 | B30: King | C30: Paul | D30: Paul King | E30: Professor | F30: NYC College of Technology | G30: Architectural Technology | H30: PKing@citytech.cuny.edu | I30: Book chapter | J30: Integrated Projects and the Development of Interdisciplinary Problem-Solving Strategies | K30: 2013 | L30: IGI Global eBooks | M30: Paul C. King | Q30: 10.4018/978-1-4666-4502-8.ch079 | R30: https://doi.org/10.4018/978-1-4666-4502-8.ch079 | S30: OpenAlex | T30: 1 | U30: High (City Tech affiliation on paper) | X30: Interdisciplinary problem solving and research skills require early preparation in two categories: critical thinking and communication. This chapter reviews the two-year process of interdisciplinary curriculum development, shaped by collaboration between the New York City Department of Education, the New York City College of Technology of the City University of New York, and City Polytechnic High School of Engineering, Architecture, and Technology. The resulting course, “Inter-Academy Integrated Projects” (IP), emphasizes multidisciplinary problem solving that includes creativity, observation, research, visual and discursive communication, and reflection. The collaborative lessons make use of project-based methodology and emphasize social responsibility. Core skills are combined across the two trimesters of IP. This endeavor will be contrasted and compared to the work of the Partnership for the 21st Century Skills by examining the use of high-impact learning practices, feedback from students and teachers, and the issues surrounding the implementation of any new curriculum. | Y30: OpenAlex | AA30: Not found | AB30: closed | AC30: School of Technology & Design | AD30: 0 | AE30: No
A31: ARCH-0030 | B31: Vaidya | C31: Sanjive | D31: Sanjive Vaidya | E31: Associate Professor | F31: NYC College of Technology | G31: Architectural Technology | H31: SVaidya@citytech.cuny.edu | I31: Grant | J31: 2014 Intersections Symposium Organizer: Conversant Technologies for Building Collaboration | K31: 2014 | S31: Dept bio | T31: 1 | U31: Medium (self-reported in faculty bio) | W31: 2014 Intersections Symposium Organizer: Conversant Technologies for Building Collaboration | AC31: School of Technology & Design | AE31: No
A32: ARCH-0034 | B32: Smith | C32: Shelley | D32: Shelley Smith | E32: Professor | F32: NYC College of Technology | G32: Architectural Technology | H32: SSmith@citytech.cuny.edu | I32: Journal article | J32: Bounding the Distinguishing Number of Infinite Graphs and Permutation Groups | K32: 2014 | L32: The Electronic Journal of Combinatorics | M32: Simon M. Smith; Mark E. Watkins | Q32: 10.37236/3046 | R32: https://doi.org/10.37236/3046 | S32: OpenAlex | T32: 1 | U32: High (City Tech affiliation on paper) | X32: A group of permutations $G$ of a set $V$ is $k$-distinguishable if there exists a partition of $V$ into $k$ cells such that only the identity permutation in $G$ fixes setwise all of the cells of the partition. The least cardinal number $k$ such that $(G,V)$ is $k$-distinguishable is its distinguishing number $D(G,V)$. In particular, a graph $\Gamma$ is $k$-distinguishable if its automorphism group $\rm{Aut}(\Gamma)$ satisfies $D(\rm{Aut}(\Gamma),V\Gamma)\leq k$.Various results in the literature demonstrate that when an infinite graph fails to have some property, then often some finite subgraph is similarly deficient. In this paper we show that whenever an infinite connected graph $\Gamma$ is not $k$-distinguishable (for a given cardinal $k$), then it contains a ball of finite radius whose distinguishing number is at least $k$. Moreover, this lower bound cannot be sharpened, since for any integer $k \geq 3$ there exists an infinite, locally finite, connected graph $\Gamma$ that is not $k$-distinguishable but in which every ball of finite radius is $k$-distinguishable.In the second half of this paper we show that a large distinguishing number for an imprimitive group $G$ is traceable to a high distinguishing number either of a block of imprimitivity or of the induced action by $G$ on the corresponding system of imprimitivity. An immediate application is to automorphism groups of infinite imprimitive graphs. These results are companion to the study of the distinguishing number of infinite primitive groups and graphs in a previous paper by the authors together with T. W. Tucker. | Y32: OpenAlex | Z32: https://www.combinatorics.org/ojs/index.php/eljc/article/download/v21i3p40/pdf | AA32: Open-access PDF (via OpenAlex) | AB32: diamond | AC32: School of Technology & Design | AD32: 3 | AE32: No
A33: ARCH-0038 | B33: Smith | C33: Shelley | D33: Shelley Smith | E33: Professor | F33: NYC College of Technology | G33: Architectural Technology | H33: SSmith@citytech.cuny.edu | I33: Journal article | J33: Infinite motion and 2-distinguishability of graphs and groups | K33: 2014 | L33: Journal of Algebraic Combinatorics | M33: Wilfried Imrich; Simon M. Smith; Thomas W. Tucker; Mark E. Watkins | Q33: 10.1007/s10801-014-0529-2 | R33: https://doi.org/10.1007/s10801-014-0529-2 | S33: OpenAlex | T33: 1 | U33: High (City Tech affiliation on paper) | X33: A group A acting faithfully on a set X is 2-distinguishable if there is a 2-coloring of X that is not preserved by any nonidentity element of A, equivalently, if there is a proper subset of X with trivial setwise stabilizer. The motion of an element a in A is the number of points of X that are moved by a, and the motion of the group A is the minimal motion of its nonidentity elements. For finite A, the Motion Lemma says that if the motion of A is large enough (specifically at least 2 log_2 |A|), then the action is 2-distinguishable. For many situations where X has a combinatorial or algebraic structure, the Motion Lemma implies the action of Aut(X) on X is 2-distinguishable in all but finitely many instances. We prove an infinitary version of the Motion Lemma for countably infinite permutation groups, which states that infinite motion is large enough to guarantee 2-distinguishability. From this we deduce a number of results, including the fact that every locally finite, connected graph whose automorphism group is countably infinite is 2-distinguishable. One cannot extend the Motion Lemma to uncountable permutation groups, but nonetheless we prove that 2-distinguishable permutation groups with infinite motion are dense in the class of groups with infinite motion. We conjecture an extension of the Motion Lemma which we expect holds for a restricted class of uncountable permutation groups, and we conclude with a list of open questions. The consequences of our results are drawn for orbit equivalence of infinite permutation groups. | Y33: OpenAlex | Z33: https://link.springer.com/content/pdf/10.1007%2Fs10801-014-0529-2.pdf | AA33: Open-access PDF (via OpenAlex) | AB33: bronze | AC33: School of Technology & Design | AD33: 24 | AE33: No
A34: ARCH-0039 | B34: Chin | C34: Ting | D34: Ting Chin | E34: Chair | F34: NYC College of Technology | G34: Architectural Technology | H34: TChin@citytech.cuny.edu | I34: Paper (venue type unclear) | J34: TECHNE Issue 01 | K34: 2014 | L34: TECHNE | M34: Ting Chin; Jason Montgomery | R34: https://openalex.org/W2916146426 | S34: OpenAlex; CUNY Academic Works | T34: 2 | U34: High (City Tech affiliation on paper); 2 sources | X34: The first issue of TECHNE, an annual publication of student work from the Department of Architecture at the New York City College of Technology. Edited by faculty members Ting Chin and Jason Montgomery, this issue includes contributions from Dean Kevin Hom, Shelley E. Smith, Ting Chin, Michael Duddy, Wendel Edwards, Claudia Hernandez-Feiks, Tim Maldonado, Harold Morales, Anthony Clemente, Patricia Paredes, Gareth Enahoro, Janil Castillo, Lia Dikigoropoulou, Andrea Garrido, Mario Alulema, Tasnuva Ahmed, Jasmine Cato, Marco Dwyer, Elvis Williams, Jean Louis Steevenson, James Rigley, Laura Calle, Moshin Alam, Carlos Mo Wu, Alondra Ramos, Tomasz Piasecki, Ekaterina Sanko, Diego Vega, Tim Maldonado, Alexander Aptekar, Jason Montgomery, Sergio Zapata, Daniel Otto, Michelle Matthews, Aaron Hollander, Shenier Torres, Nataly Bautista, Keith Alfaro, Vladislav Valentinov, Farhana Rahman, Brendan Sigvardsson Cooney, Paul King, Joseph Vidich, Patrick Delorey, Charles Walker, Omar Teles, Ariel Ortiz, Yael Malaev, Khadeeja Din, Chantal Manning, Brian Lall, Loyra Nunez, Eric Ramirez, Esteban Beita, Margarita Salas, William Valdez, Amira Joelson, Agustin Maldonado, Vesselin Milev, Raymond Jimenez, Danny Mieles, Vlad Dunda, Vera Orlova, Sauda Belkaus, Charles Able, Severino Alfonso, Zachary Downey, Anne Leonhardt, Anatoly Plotkin, Kwong Liu, Maksim Drapey, Maciej Stelmach, Ariel Mejia, Andriy Boychuk, Rafael Aquino,Mahshid Kandi, Kento Kawai, Evgenia Melnikova, Irina Nechaeva, Trung Nguyen, Jonathan Rincon, Rawle Smith, and Erick Ramirez. Table of Contents INTRODUCTIONS A Word From The Dean: Kevin Hom, Dean of the School of Technology and Design Introducing The Department: Shelley E. Smith, Associate Professor, Chair of the Department of Architectural Technology TECHNÄ: Ting Chin, Assistant Professor REFLECTIONS Anticipation: Michael Duddy, Assistant Professor What is Architecture?: Lia Dikigoropoulou, Assistant Professor Experiencing Architecture: Andrea Garrido An Architectural Pilgrimage: France Mario Alulema A Change of Heart: Tasnuva Ahmed Remembering Prof. Berensmann: Tim Maldonado, Professor PEDAGOGIES Teaching Architecture: Alexander Aptekar, Assistant Professor; Wendel Edwards, Associate Professor; Claudia Hernandez, Substitute Professor; Paul King, Associate Professor; Tim Maldonado, Professor PERSPECTIVES Learning Architecture: Janil Castillo, Anthony Clemente, Gareth Enahoro, Harold Morales, Patricia Paredes VISUAL STUDIES + FOUNDATIONS DESIGN SEQUENCE Process+ Workflow in Architectural Education: Jason Montgomery, Assistant Professor | Y34: CUNY Academic Works | Z34: https://academicworks.cuny.edu/context/ny_techne/article/1000/viewcontent/TECHNE_2014_CUNY2.pdf | AA34: Not found | AB34: closed | AC34: School of Technology & Design | AD34: 0 | AE34: No
A35: ARCH-0040 | B35: Vaidya | C35: Sanjive | D35: Sanjive Vaidya | E35: Associate Professor | F35: NYC College of Technology | G35: Architectural Technology | H35: SVaidya@citytech.cuny.edu | I35: Grant | J35: 2015 Intersections Symposium Organizer: Digital Intelligence: Conversations on Sensing and Simulation | K35: 2015 | S35: Dept bio | T35: 1 | U35: Medium (self-reported in faculty bio) | W35: 2015 Intersections Symposium Organizer: Digital Intelligence: Conversations on Sensing and Simulation | AC35: School of Technology & Design | AE35: No
A36: ARCH-0041 | B36: Smith | C36: Shelley | D36: Shelley Smith | E36: Professor | F36: NYC College of Technology | G36: Architectural Technology | H36: SSmith@citytech.cuny.edu | I36: Journal article | J36: A classification of primitive permutation groups with finite stabilizers | K36: 2015 | L36: Journal of Algebra | M36: Simon M. Smith | Q36: 10.1016/j.jalgebra.2015.01.023 | R36: https://doi.org/10.1016/j.jalgebra.2015.01.023 | S36: OpenAlex | T36: 1 | U36: High (City Tech affiliation on paper) | Z36: https://www.sciencedirect.com/science/article/pii/S0021869315000629/pdf | AA36: Open-access PDF (via OpenAlex) | AB36: bronze | AC36: School of Technology & Design | AD36: 8 | AE36: No
A37: ARCH-0042 | B37: Smith | C37: Shelley | D37: Shelley Smith | E37: Professor | F37: NYC College of Technology | G37: Architectural Technology | H37: SSmith@citytech.cuny.edu | I37: Journal article | J37: Cary Carson and Carl Lounsbury, eds. The Chesapeake House: Architectural Investigations by Colonial Williamsburg. Chapel Hill: University of North Carolina Press, 2013. xi+488 pp.; 150 color plates and 200 halftones, notes, contributors, index. $60.00. | K37: 2015 | L37: Winterthur Portfolio | M37: Shelley E. Smith | Q37: 10.1086/680459 | R37: https://doi.org/10.1086/680459 | S37: OpenAlex | T37: 1 | U37: High (City Tech affiliation on paper) | AA37: Not found | AB37: closed | AC37: School of Technology & Design | AD37: 0 | AE37: No
A38: ARCH-0045 | B38: Bouratoglou | C38: Jill | D38: Jill Bouratoglou | E38: Associate Professor | F38: NYC College of Technology | G38: Architectural Technology | H38: JBouratoglou@citytech.cuny.edu | I38: Journal article | J38: Global Interaction into the Traditional Design Studios through Blogs | K38: 2015 | L38: Athens Journal of Architecture | M38: Jill Bouratoglou; Lia Dikigoropoulou | Q38: 10.30958/aja.1-2-4 | R38: https://doi.org/10.30958/aja.1-2-4 | S38: OpenAlex | T38: 1 | U38: High (City Tech affiliation on paper) | X38:  Provide students with new and unique | Y38: OpenAlex | Z38: https://doi.org/10.30958/aja.1-2-4 | AA38: Open-access PDF (via OpenAlex) | AB38: diamond | AC38: School of Technology & Design | AD38: 1 | AE38: No
A39: ARCH-0046 | B39: Dikigoropoulou | C39: Lia | D39: Lia Dikigoropoulou | E39: Associate Professor | F39: NYC College of Technology | G39: Architectural Technology | H39: LDikigoropoulou@citytech.cuny.edu | I39: Journal article | J39: Global Interaction into the Traditional Design Studios through Blogs | K39: 2015 | L39: Athens Journal of Architecture | M39: Jill Bouratoglou; Lia Dikigoropoulou | Q39: 10.30958/aja.1-2-4 | R39: https://doi.org/10.30958/aja.1-2-4 | S39: OpenAlex | T39: 1 | U39: High (City Tech affiliation on paper) | X39:  Provide students with new and unique | Y39: OpenAlex | Z39: https://doi.org/10.30958/aja.1-2-4 | AA39: Open-access PDF (via OpenAlex) | AB39: diamond | AC39: School of Technology & Design | AD39: 1 | AE39: No
A40: ARCH-0049 | B40: Dikigoropoulou | C40: Lia | D40: Lia Dikigoropoulou | E40: Associate Professor | F40: NYC College of Technology | G40: Architectural Technology | H40: LDikigoropoulou@citytech.cuny.edu | I40: Conference paper | J40: Study Abroad - Belize - Architectural Technology Students Design and Build | K40: 2015 | L40: CUNY Academic Works (City University of New York) | M40: Lia Dikigoropoulou | R40: https://openalex.org/W2618761520 | S40: OpenAlex; CUNY Academic Works | T40: 2 | U40: High (City Tech affiliation on paper); 2 sources | Z40: https://academicworks.cuny.edu/context/ufs_conf/article/1002/viewcontent/Global_Ed_Conf_Poster_DIKIGOROPOULOU_Belize.pdf | AA40: Not found | AB40: closed | AC40: School of Technology & Design | AD40: 0 | AE40: No
...

Sheet Faculty
A1: SNo | B1: LastName | C1: FirstName | D1: FullName | E1: Title | F1: College | G1: Department | H1: Email | I1: Office | J1: DirectoryProfile | K1: ORCID | L1: HasProfile | M1: TotalPubs | N1: Citations | O1: Hindex | P1: Iindex | Q1: ScholarProfile | R1: ScholarInterests | S1: ScholarCheckedOn | T1: ItemsCollected | U1: Journal article | V1: Conference paper | W1: Book | X1: Book chapter | Y1: Conference presentation | Z1: Technical report | AA1: Paper (venue type unclear) | AB1: Patent | AC1: Grant | AD1: WithDOI | AE1: FoundIn: Dept bio | AF1: FoundIn: Academic Works | AG1: FoundIn: ORCID | AH1: FoundIn: Crossref | AI1: FoundIn: NSF | AJ1: FoundIn: Google Scholar | AK1: Notes | AL1: School | AM1: Status | AN1: Preprint | AO1: Dataset | AP1: Dissertation | AQ1: Open educational resource | AR1: Other | AS1: FoundIn: OpenAlex | AT1: FoundIn: NIH | AU1: AI tier | AV1: AI items (confirmed) | AW1: Items to check
A2: 1 | B2: Almeida | C2: Nora | D2: Nora Almeida | E2: Associate Professor/Instruction, Reference | F2: NYC College of Technology | G2: Library | H2: NAlmeida@citytech.cuny.edu | I2: L-543D | J2: https://www.citytech.cuny.edu/faculty/nalmeida | L2: FALSE | T2: =COUNTIFS(Items!$H$2:$H$5547,$H2) | U2: =COUNTIFS(Items!$H$2:$H$5547,$H2,Items!$I$2:$I$5547,"Journal article") | V2: =COUNTIFS(Items!$H$2:$H$5547,$H2,Items!$I$2:$I$5547,"Conference paper") | W2: =COUNTIFS(Items!$H$2:$H$5547,$H2,Items!$I$2:$I$5547,"Book") | X2: =COUNTIFS(Items!$H$2:$H$5547,$H2,Items!$I$2:$I$5547,"Book chapter") | Y2: =COUNTIFS(Items!$H$2:$H$5547,$H2,Items!$I$2:$I$5547,"Conference presentation") | Z2: =COUNTIFS(Items!$H$2:$H$5547,$H2,Items!$I$2:$I$5547,"Technical report") | AA2: =COUNTIFS(Items!$H$2:$H$5547,$H2,Items!$I$2:$I$5547,"Paper (venue type unclear)") | AB2: =COUNTIFS(Items!$H$2:$H$5547,$H2,Items!$I$2:$I$5547,"Patent") | AC2: =COUNTIFS(Items!$H$2:$H$5547,$H2,Items!$I$2:$I$5547,"Grant") | AD2: =COUNTIFS(Items!$H$2:$H$5547,$H2,Items!$Q$2:$Q$5547,"<>") | AE2: =COUNTIFS(Items!$H$2:$H$5547,$H2,Items!$S$2:$S$5547,"*Dept bio*") | AF2: =COUNTIFS(Items!$H$2:$H$5547,$H2,Items!$S$2:$S$5547,"*CUNY Academic Works*") | AG2: =COUNTIFS(Items!$H$2:$H$5547,$H2,Items!$S$2:$S$5547,"*ORCID*") | AH2: =COUNTIFS(Items!$H$2:$H$5547,$H2,Items!$S$2:$S$5547,"*Crossref*") | AI2: =COUNTIFS(Items!$H$2:$H$5547,$H2,Items!$S$2:$S$5547,"*NSF*") | AJ2: =COUNTIFS(Items!$H$2:$H$5547,$H2,Items!$S$2:$S$5547,"*Google Scholar*") | AL2: Library | AM2: Full-time | AN2: =COUNTIFS(Items!$H$2:$H$5547,$H2,Items!$I$2:$I$5547,"Preprint") | AO2: =COUNTIFS(Items!$H$2:$H$5547,$H2,Items!$I$2:$I$5547,"Dataset") | AP2: =COUNTIFS(Items!$H$2:$H$5547,$H2,Items!$I$2:$I$5547,"Dissertation") | AQ2: =COUNTIFS(Items!$H$2:$H$5547,$H2,Items!$I$2:$I$5547,"Open educational resource") | AR2: =COUNTIFS(Items!$H$2:$H$5547,$H2,Items!$I$2:$I$5547,"Other") | AS2: =COUNTIFS(Items!$H$2:$H$5547,$H2,Items!$S$2:$S$5547,"*OpenAlex*") | AT2: =COUNTIFS(Items!$H$2:$H$5547,$H2,Items!$S$2:$S$5547,"*NIH*") | AV2: =COUNTIFS(Items!$H$2:$H$5547,$H2,Items!$AE$2:$AE$5547,"Yes") | AW2: 0
A3: 2 | B3: Berger | C3: Monica | D3: Monica Berger | E3: Professor/Instruction and Scholarly Communications Librarian | F3: NYC College of Technology | G3: Library | H3: MBerger@citytech.cuny.edu | I3: L-543A | J3: https://www.citytech.cuny.edu/faculty/mberger | L3: FALSE | T3: =COUNTIFS(Items!$H$2:$H$5547,$H3) | U3: =COUNTIFS(Items!$H$2:$H$5547,$H3,Items!$I$2:$I$5547,"Journal article") | V3: =COUNTIFS(Items!$H$2:$H$5547,$H3,Items!$I$2:$I$5547,"Conference paper") | W3: =COUNTIFS(Items!$H$2:$H$5547,$H3,Items!$I$2:$I$5547,"Book") | X3: =COUNTIFS(Items!$H$2:$H$5547,$H3,Items!$I$2:$I$5547,"Book chapter") | Y3: =COUNTIFS(Items!$H$2:$H$5547,$H3,Items!$I$2:$I$5547,"Conference presentation") | Z3: =COUNTIFS(Items!$H$2:$H$5547,$H3,Items!$I$2:$I$5547,"Technical report") | AA3: =COUNTIFS(Items!$H$2:$H$5547,$H3,Items!$I$2:$I$5547,"Paper (venue type unclear)") | AB3: =COUNTIFS(Items!$H$2:$H$5547,$H3,Items!$I$2:$I$5547,"Patent") | AC3: =COUNTIFS(Items!$H$2:$H$5547,$H3,Items!$I$2:$I$5547,"Grant") | AD3: =COUNTIFS(Items!$H$2:$H$5547,$H3,Items!$Q$2:$Q$5547,"<>") | AE3: =COUNTIFS(Items!$H$2:$H$5547,$H3,Items!$S$2:$S$5547,"*Dept bio*") | AF3: =COUNTIFS(Items!$H$2:$H$5547,$H3,Items!$S$2:$S$5547,"*CUNY Academic Works*") | AG3: =COUNTIFS(Items!$H$2:$H$5547,$H3,Items!$S$2:$S$5547,"*ORCID*") | AH3: =COUNTIFS(Items!$H$2:$H$5547,$H3,Items!$S$2:$S$5547,"*Crossref*") | AI3: =COUNTIFS(Items!$H$2:$H$5547,$H3,Items!$S$2:$S$5547,"*NSF*") | AJ3: =COUNTIFS(Items!$H$2:$H$5547,$H3,Items!$S$2:$S$5547,"*Google Scholar*") | AL3: Library | AM3: Full-time | AN3: =COUNTIFS(Items!$H$2:$H$5547,$H3,Items!$I$2:$I$5547,"Preprint") | AO3: =COUNTIFS(Items!$H$2:$H$5547,$H3,Items!$I$2:$I$5547,"Dataset") | AP3: =COUNTIFS(Items!$H$2:$H$5547,$H3,Items!$I$2:$I$5547,"Dissertation") | AQ3: =COUNTIFS(Items!$H$2:$H$5547,$H3,Items!$I$2:$I$5547,"Open educational resource") | AR3: =COUNTIFS(Items!$H$2:$H$5547,$H3,Items!$I$2:$I$5547,"Other") | AS3: =COUNTIFS(Items!$H$2:$H$5547,$H3,Items!$S$2:$S$5547,"*OpenAlex*") | AT3: =COUNTIFS(Items!$H$2:$H$5547,$H3,Items!$S$2:$S$5547,"*NIH*") | AU3: Some AI work | AV3: =COUNTIFS(Items!$H$2:$H$5547,$H3,Items!$AE$2:$AE$5547,"Yes") | AW3: 0
A4: 3 | B4: Clyde | C4: Wanett | D4: Wanett Clyde | E4: Associate Professor | F4: NYC College of Technology | G4: Library | H4: WClyde@citytech.cuny.edu | I4: L-539C | J4: https://www.citytech.cuny.edu/faculty/wclyde | L4: FALSE | T4: =COUNTIFS(Items!$H$2:$H$5547,$H4) | U4: =COUNTIFS(Items!$H$2:$H$5547,$H4,Items!$I$2:$I$5547,"Journal article") | V4: =COUNTIFS(Items!$H$2:$H$5547,$H4,Items!$I$2:$I$5547,"Conference paper") | W4: =COUNTIFS(Items!$H$2:$H$5547,$H4,Items!$I$2:$I$5547,"Book") | X4: =COUNTIFS(Items!$H$2:$H$5547,$H4,Items!$I$2:$I$5547,"Book chapter") | Y4: =COUNTIFS(Items!$H$2:$H$5547,$H4,Items!$I$2:$I$5547,"Conference presentation") | Z4: =COUNTIFS(Items!$H$2:$H$5547,$H4,Items!$I$2:$I$5547,"Technical report") | AA4: =COUNTIFS(Items!$H$2:$H$5547,$H4,Items!$I$2:$I$5547,"Paper (venue type unclear)") | AB4: =COUNTIFS(Items!$H$2:$H$5547,$H4,Items!$I$2:$I$5547,"Patent") | AC4: =COUNTIFS(Items!$H$2:$H$5547,$H4,Items!$I$2:$I$5547,"Grant") | AD4: =COUNTIFS(Items!$H$2:$H$5547,$H4,Items!$Q$2:$Q$5547,"<>") | AE4: =COUNTIFS(Items!$H$2:$H$5547,$H4,Items!$S$2:$S$5547,"*Dept bio*") | AF4: =COUNTIFS(Items!$H$2:$H$5547,$H4,Items!$S$2:$S$5547,"*CUNY Academic Works*") | AG4: =COUNTIFS(Items!$H$2:$H$5547,$H4,Items!$S$2:$S$5547,"*ORCID*") | AH4: =COUNTIFS(Items!$H$2:$H$5547,$H4,Items!$S$2:$S$5547,"*Crossref*") | AI4: =COUNTIFS(Items!$H$2:$H$5547,$H4,Items!$S$2:$S$5547,"*NSF*") | AJ4: =COUNTIFS(Items!$H$2:$H$5547,$H4,Items!$S$2:$S$5547,"*Google Scholar*") | AL4: Library | AM4: Full-time | AN4: =COUNTIFS(Items!$H$2:$H$5547,$H4,Items!$I$2:$I$5547,"Preprint") | AO4: =COUNTIFS(Items!$H$2:$H$5547,$H4,Items!$I$2:$I$5547,"Dataset") | AP4: =COUNTIFS(Items!$H$2:$H$5547,$H4,Items!$I$2:$I$5547,"Dissertation") | AQ4: =COUNTIFS(Items!$H$2:$H$5547,$H4,Items!$I$2:$I$5547,"Open educational resource") | AR4: =COUNTIFS(Items!$H$2:$H$5547,$H4,Items!$I$2:$I$5547,"Other") | AS4: =COUNTIFS(Items!$H$2:$H$5547,$H4,Items!$S$2:$S$5547,"*OpenAlex*") | AT4: =COUNTIFS(Items!$H$2:$H$5547,$H4,Items!$S$2:$S$5547,"*NIH*") | AV4: =COUNTIFS(Items!$H$2:$H$5547,$H4,Items!$AE$2:$AE$5547,"Yes") | AW4: 0
